[2025-01-23T09:56:20.958+0000] {local_task_job_runner.py:123} INFO - ::group::Pre task execution logs
[2025-01-23T09:56:20.974+0000] {taskinstance.py:2613} INFO - Dependencies all met for dep_context=non-requeueable deps ti=<TaskInstance: elt_dbt.dbt_run scheduled__2025-01-22T00:00:00+00:00 [queued]>
[2025-01-23T09:56:20.994+0000] {taskinstance.py:2613} INFO - Dependencies all met for dep_context=requeueable deps ti=<TaskInstance: elt_dbt.dbt_run scheduled__2025-01-22T00:00:00+00:00 [queued]>
[2025-01-23T09:56:20.995+0000] {taskinstance.py:2866} INFO - Starting attempt 1 of 1
[2025-01-23T09:56:21.014+0000] {taskinstance.py:2889} INFO - Executing <Task(BashOperator): dbt_run> on 2025-01-22 00:00:00+00:00
[2025-01-23T09:56:21.018+0000] {warnings.py:112} WARNING - /home/***/.local/lib/python3.12/site-packages/***/task/task_runner/standard_task_runner.py:70: DeprecationWarning: This process (pid=7503) is multi-threaded, use of fork() may lead to deadlocks in the child.
  pid = os.fork()

[2025-01-23T09:56:21.020+0000] {standard_task_runner.py:72} INFO - Started process 7504 to run task
[2025-01-23T09:56:21.020+0000] {standard_task_runner.py:104} INFO - Running: ['***', 'tasks', 'run', 'elt_dbt', 'dbt_run', 'scheduled__2025-01-22T00:00:00+00:00', '--job-id', '8', '--raw', '--subdir', 'DAGS_FOLDER/dbt_process.py', '--cfg-path', '/tmp/tmphy_1ae7d']
[2025-01-23T09:56:21.022+0000] {standard_task_runner.py:105} INFO - Job 8: Subtask dbt_run
[2025-01-23T09:56:21.067+0000] {task_command.py:467} INFO - Running <TaskInstance: elt_dbt.dbt_run scheduled__2025-01-22T00:00:00+00:00 [running]> on host c28716311b4b
[2025-01-23T09:56:21.142+0000] {taskinstance.py:3132} INFO - Exporting env vars: AIRFLOW_CTX_DAG_OWNER='***' AIRFLOW_CTX_DAG_ID='elt_dbt' AIRFLOW_CTX_TASK_ID='dbt_run' AIRFLOW_CTX_EXECUTION_DATE='2025-01-22T00:00:00+00:00' AIRFLOW_CTX_TRY_NUMBER='1' AIRFLOW_CTX_DAG_RUN_ID='scheduled__2025-01-22T00:00:00+00:00'
[2025-01-23T09:56:21.143+0000] {taskinstance.py:731} INFO - ::endgroup::
[2025-01-23T09:56:21.145+0000] {subprocess.py:78} INFO - Tmp dir root location: /tmp
[2025-01-23T09:56:21.147+0000] {subprocess.py:88} INFO - Running command: ['/usr/bin/bash', '-c', 'cd /opt/***/include/dbt/northwind/ && dbt run --select warehouse']
[2025-01-23T09:56:21.153+0000] {subprocess.py:99} INFO - Output:
[2025-01-23T09:56:22.777+0000] {subprocess.py:106} INFO - [0m09:56:22  Running with dbt=1.8.7
[2025-01-23T09:56:23.464+0000] {subprocess.py:106} INFO - [0m09:56:23  Registered adapter: snowflake=1.8.4
[2025-01-23T09:56:23.613+0000] {subprocess.py:106} INFO - [0m09:56:23  [[33mWARNING[0m]: Configuration paths exist in your dbt_project.yml file which do not apply to any resources.
[2025-01-23T09:56:23.613+0000] {subprocess.py:106} INFO - There are 1 unused configuration paths:
[2025-01-23T09:56:23.613+0000] {subprocess.py:106} INFO - - models.northwind.example
[2025-01-23T09:56:23.705+0000] {subprocess.py:106} INFO - [0m09:56:23  Found 19 seeds, 7 models, 1 source, 459 macros
[2025-01-23T09:56:23.706+0000] {subprocess.py:106} INFO - [0m09:56:23
[2025-01-23T09:56:24.650+0000] {subprocess.py:106} INFO - [0m09:56:24  Concurrency: 200 threads (target='dev')
[2025-01-23T09:56:24.650+0000] {subprocess.py:106} INFO - [0m09:56:24
[2025-01-23T09:56:24.701+0000] {subprocess.py:106} INFO - [0m09:56:24  1 of 7 START sql view model public.dim_customer ................................ [RUN]
[2025-01-23T09:56:24.703+0000] {subprocess.py:106} INFO - [0m09:56:24  2 of 7 START sql view model public.dim_date .................................... [RUN]
[2025-01-23T09:56:24.705+0000] {subprocess.py:106} INFO - [0m09:56:24  4 of 7 START sql view model public.dim_products ................................ [RUN]
[2025-01-23T09:56:24.705+0000] {subprocess.py:106} INFO - [0m09:56:24  5 of 7 START sql view model public.fact_inventory .............................. [RUN]
[2025-01-23T09:56:24.706+0000] {subprocess.py:106} INFO - [0m09:56:24  6 of 7 START sql view model public.fact_purchase_order ......................... [RUN]
[2025-01-23T09:56:24.717+0000] {subprocess.py:106} INFO - [0m09:56:24  7 of 7 START sql view model public.fact_sales .................................. [RUN]
[2025-01-23T09:56:24.724+0000] {subprocess.py:106} INFO - [0m09:56:24  3 of 7 START sql view model public.dim_employees ............................... [RUN]
[2025-01-23T09:56:25.325+0000] {subprocess.py:106} INFO - [0m09:56:25  2 of 7 ERROR creating sql view model public.dim_date ........................... [[31mERROR[0m in 0.62s]
[2025-01-23T09:56:25.452+0000] {subprocess.py:106} INFO - [0m09:56:25  5 of 7 OK created sql view model public.fact_inventory ......................... [[32mSUCCESS 1[0m in 0.74s]
[2025-01-23T09:56:25.457+0000] {subprocess.py:106} INFO - [0m09:56:25  4 of 7 OK created sql view model public.dim_products ........................... [[32mSUCCESS 1[0m in 0.75s]
[2025-01-23T09:56:25.538+0000] {subprocess.py:106} INFO - [0m09:56:25  7 of 7 OK created sql view model public.fact_sales ............................. [[32mSUCCESS 1[0m in 0.82s]
[2025-01-23T09:56:25.557+0000] {subprocess.py:106} INFO - [0m09:56:25  1 of 7 OK created sql view model public.dim_customer ........................... [[32mSUCCESS 1[0m in 0.85s]
[2025-01-23T09:56:25.592+0000] {subprocess.py:106} INFO - [0m09:56:25  3 of 7 OK created sql view model public.dim_employees .......................... [[32mSUCCESS 1[0m in 0.85s]
[2025-01-23T09:56:25.656+0000] {subprocess.py:106} INFO - [0m09:56:25  6 of 7 OK created sql view model public.fact_purchase_order .................... [[32mSUCCESS 1[0m in 0.95s]
[2025-01-23T09:56:25.679+0000] {subprocess.py:106} INFO - [0m09:56:25
[2025-01-23T09:56:25.682+0000] {subprocess.py:106} INFO - [0m09:56:25  Finished running 7 view models in 0 hours 0 minutes and 1.97 seconds (1.97s).
[2025-01-23T09:56:25.710+0000] {subprocess.py:106} INFO - [0m09:56:25
[2025-01-23T09:56:25.711+0000] {subprocess.py:106} INFO - [0m09:56:25  [31mCompleted with 1 error and 0 warnings:[0m
[2025-01-23T09:56:25.711+0000] {subprocess.py:106} INFO - [0m09:56:25
[2025-01-23T09:56:25.712+0000] {subprocess.py:106} INFO - [0m09:56:25    Database Error in model dim_date (models/warehouse/dim_date.sql)
[2025-01-23T09:56:25.712+0000] {subprocess.py:106} INFO -   001003 (42000): SQL compilation error:
[2025-01-23T09:56:25.712+0000] {subprocess.py:106} INFO -   syntax error line 27 at position 14 unexpected ';'.
[2025-01-23T09:56:25.712+0000] {subprocess.py:106} INFO -   compiled code at target/run/northwind/models/warehouse/dim_date.sql
[2025-01-23T09:56:25.713+0000] {subprocess.py:106} INFO - [0m09:56:25
[2025-01-23T09:56:25.713+0000] {subprocess.py:106} INFO - [0m09:56:25  Done. PASS=6 WARN=0 ERROR=1 SKIP=0 TOTAL=7
[2025-01-23T09:56:27.703+0000] {subprocess.py:110} INFO - Command exited with return code 1
[2025-01-23T09:56:27.737+0000] {taskinstance.py:3311} ERROR - Task failed with exception
Traceback (most recent call last):
  File "/home/airflow/.local/lib/python3.12/site-packages/airflow/models/taskinstance.py", line 767, in _execute_task
    result = _execute_callable(context=context, **execute_callable_kwargs)
             ^^^^^^^^^^^^^^^^^^^^^^^^^^^^^^^^^^^^^^^^^^^^^^^^^^^^^^^^^^^^^
  File "/home/airflow/.local/lib/python3.12/site-packages/airflow/models/taskinstance.py", line 733, in _execute_callable
    return ExecutionCallableRunner(
           ^^^^^^^^^^^^^^^^^^^^^^^^
  File "/home/airflow/.local/lib/python3.12/site-packages/airflow/utils/operator_helpers.py", line 252, in run
    return self.func(*args, **kwargs)
           ^^^^^^^^^^^^^^^^^^^^^^^^^^
  File "/home/airflow/.local/lib/python3.12/site-packages/airflow/models/baseoperator.py", line 422, in wrapper
    return func(self, *args, **kwargs)
           ^^^^^^^^^^^^^^^^^^^^^^^^^^^
  File "/home/airflow/.local/lib/python3.12/site-packages/airflow/operators/bash.py", line 276, in execute
    raise AirflowException(
airflow.exceptions.AirflowException: Bash command failed. The command returned a non-zero exit code 1.
[2025-01-23T09:56:27.750+0000] {taskinstance.py:1225} INFO - Marking task as FAILED. dag_id=elt_dbt, task_id=dbt_run, run_id=scheduled__2025-01-22T00:00:00+00:00, execution_date=20250122T000000, start_date=20250123T095620, end_date=20250123T095627
[2025-01-23T09:56:27.776+0000] {taskinstance.py:340} INFO - ::group::Post task execution logs
[2025-01-23T09:56:27.778+0000] {standard_task_runner.py:124} ERROR - Failed to execute job 8 for task dbt_run (Bash command failed. The command returned a non-zero exit code 1.; 7504)
Traceback (most recent call last):
  File "/home/airflow/.local/lib/python3.12/site-packages/airflow/task/task_runner/standard_task_runner.py", line 117, in _start_by_fork
    ret = args.func(args, dag=self.dag)
          ^^^^^^^^^^^^^^^^^^^^^^^^^^^^^
  File "/home/airflow/.local/lib/python3.12/site-packages/airflow/cli/cli_config.py", line 49, in command
    return func(*args, **kwargs)
           ^^^^^^^^^^^^^^^^^^^^^
  File "/home/airflow/.local/lib/python3.12/site-packages/airflow/utils/cli.py", line 116, in wrapper
    return f(*args, **kwargs)
           ^^^^^^^^^^^^^^^^^^
  File "/home/airflow/.local/lib/python3.12/site-packages/airflow/cli/commands/task_command.py", line 483, in task_run
    task_return_code = _run_task_by_selected_method(args, _dag, ti)
                       ^^^^^^^^^^^^^^^^^^^^^^^^^^^^^^^^^^^^^^^^^^^^
  File "/home/airflow/.local/lib/python3.12/site-packages/airflow/cli/commands/task_command.py", line 256, in _run_task_by_selected_method
    return _run_raw_task(args, ti)
           ^^^^^^^^^^^^^^^^^^^^^^^
  File "/home/airflow/.local/lib/python3.12/site-packages/airflow/cli/commands/task_command.py", line 341, in _run_raw_task
    return ti._run_raw_task(
           ^^^^^^^^^^^^^^^^^
  File "/home/airflow/.local/lib/python3.12/site-packages/airflow/utils/session.py", line 97, in wrapper
    return func(*args, session=session, **kwargs)
           ^^^^^^^^^^^^^^^^^^^^^^^^^^^^^^^^^^^^^^
  File "/home/airflow/.local/lib/python3.12/site-packages/airflow/models/taskinstance.py", line 3005, in _run_raw_task
    return _run_raw_task(
           ^^^^^^^^^^^^^^
  File "/home/airflow/.local/lib/python3.12/site-packages/airflow/models/taskinstance.py", line 273, in _run_raw_task
    TaskInstance._execute_task_with_callbacks(
  File "/home/airflow/.local/lib/python3.12/site-packages/airflow/models/taskinstance.py", line 3159, in _execute_task_with_callbacks
    result = self._execute_task(context, task_orig)
             ^^^^^^^^^^^^^^^^^^^^^^^^^^^^^^^^^^^^^^
  File "/home/airflow/.local/lib/python3.12/site-packages/airflow/models/taskinstance.py", line 3183, in _execute_task
    return _execute_task(self, context, task_orig)
           ^^^^^^^^^^^^^^^^^^^^^^^^^^^^^^^^^^^^^^^
  File "/home/airflow/.local/lib/python3.12/site-packages/airflow/models/taskinstance.py", line 767, in _execute_task
    result = _execute_callable(context=context, **execute_callable_kwargs)
             ^^^^^^^^^^^^^^^^^^^^^^^^^^^^^^^^^^^^^^^^^^^^^^^^^^^^^^^^^^^^^
  File "/home/airflow/.local/lib/python3.12/site-packages/airflow/models/taskinstance.py", line 733, in _execute_callable
    return ExecutionCallableRunner(
           ^^^^^^^^^^^^^^^^^^^^^^^^
  File "/home/airflow/.local/lib/python3.12/site-packages/airflow/utils/operator_helpers.py", line 252, in run
    return self.func(*args, **kwargs)
           ^^^^^^^^^^^^^^^^^^^^^^^^^^
  File "/home/airflow/.local/lib/python3.12/site-packages/airflow/models/baseoperator.py", line 422, in wrapper
    return func(self, *args, **kwargs)
           ^^^^^^^^^^^^^^^^^^^^^^^^^^^
  File "/home/airflow/.local/lib/python3.12/site-packages/airflow/operators/bash.py", line 276, in execute
    raise AirflowException(
airflow.exceptions.AirflowException: Bash command failed. The command returned a non-zero exit code 1.
[2025-01-23T09:56:27.799+0000] {local_task_job_runner.py:266} INFO - Task exited with return code 1
[2025-01-23T09:56:27.836+0000] {taskinstance.py:3895} INFO - 0 downstream tasks scheduled from follow-on schedule check
[2025-01-23T09:56:27.843+0000] {local_task_job_runner.py:245} INFO - ::endgroup::
